Workbook

Sheet 1.报价汇总
B2: 体彩衍生品商城小程序 — 系统报价汇总
B3: 范围：C 端小程序 + 运营管理后台（功能点细化到三级模块）
B5: C 端一级模块 | C5: 人天 | D5: 金额（元） | E5: 后台一级模块 | F5: 人天 | G5: 金额（元） | H5: 合计人天 | I5: 合计金额（元）
B6: A. 首页 | C6: =SUMIF('2.C端模块'!C:C,B6,'2.C端模块'!G:G) | D6: =SUMIF('2.C端模块'!C:C,B6,'2.C端模块'!I:I) | E6: H. 工作台 | F6: =SUMIF('3.后台模块'!C:C,E6,'3.后台模块'!G:G) | G6: =SUMIF('3.后台模块'!C:C,E6,'3.后台模块'!I:I) | H6: =IFERROR(C6,0)+IFERROR(F6,0) | I6: =IFERROR(D6,0)+IFERROR(G6,0)
B7: B. 商品 | C7: =SUMIF('2.C端模块'!C:C,B7,'2.C端模块'!G:G) | D7: =SUMIF('2.C端模块'!C:C,B7,'2.C端模块'!I:I) | E7: I. 商品管理 | F7: =SUMIF('3.后台模块'!C:C,E7,'3.后台模块'!G:G) | G7: =SUMIF('3.后台模块'!C:C,E7,'3.后台模块'!I:I) | H7: =IFERROR(C7,0)+IFERROR(F7,0) | I7: =IFERROR(D7,0)+IFERROR(G7,0)
B8: C. 购物车 | C8: =SUMIF('2.C端模块'!C:C,B8,'2.C端模块'!G:G) | D8: =SUMIF('2.C端模块'!C:C,B8,'2.C端模块'!I:I) | E8: J. 订单管理 | F8: =SUMIF('3.后台模块'!C:C,E8,'3.后台模块'!G:G) | G8: =SUMIF('3.后台模块'!C:C,E8,'3.后台模块'!I:I) | H8: =IFERROR(C8,0)+IFERROR(F8,0) | I8: =IFERROR(D8,0)+IFERROR(G8,0)
B9: D. 订单 | C9: =SUMIF('2.C端模块'!C:C,B9,'2.C端模块'!G:G) | D9: =SUMIF('2.C端模块'!C:C,B9,'2.C端模块'!I:I) | E9: K. 渠道供货 | F9: =SUMIF('3.后台模块'!C:C,E9,'3.后台模块'!G:G) | G9: =SUMIF('3.后台模块'!C:C,E9,'3.后台模块'!I:I) | H9: =IFERROR(C9,0)+IFERROR(F9,0) | I9: =IFERROR(D9,0)+IFERROR(G9,0)
B10: E. 用户 | C10: =SUMIF('2.C端模块'!C:C,B10,'2.C端模块'!G:G) | D10: =SUMIF('2.C端模块'!C:C,B10,'2.C端模块'!I:I) | E10: L. 地区营销 | F10: =SUMIF('3.后台模块'!C:C,E10,'3.后台模块'!G:G) | G10: =SUMIF('3.后台模块'!C:C,E10,'3.后台模块'!I:I) | H10: =IFERROR(C10,0)+IFERROR(F10,0) | I10: =IFERROR(D10,0)+IFERROR(G10,0)
B11: F. 公共能力 | C11: =SUMIF('2.C端模块'!C:C,B11,'2.C端模块'!G:G) | D11: =SUMIF('2.C端模块'!C:C,B11,'2.C端模块'!I:I) | E11: M. 财务管理 | F11: =SUMIF('3.后台模块'!C:C,E11,'3.后台模块'!G:G) | G11: =SUMIF('3.后台模块'!C:C,E11,'3.后台模块'!I:I) | H11: =IFERROR(C11,0)+IFERROR(F11,0) | I11: =IFERROR(D11,0)+IFERROR(G11,0)
E12: G. 系统认证 | F12: =SUMIF('3.后台模块'!C:C,E12,'3.后台模块'!G:G) | G12: =SUMIF('3.后台模块'!C:C,E12,'3.后台模块'!I:I) | H12: =IFERROR(C12,0)+IFERROR(F12,0) | I12: =IFERROR(D12,0)+IFERROR(G12,0)
E13: N. 系统配置 | F13: =SUMIF('3.后台模块'!C:C,E13,'3.后台模块'!G:G) | G13: =SUMIF('3.后台模块'!C:C,E13,'3.后台模块'!I:I) | H13: =IFERROR(C13,0)+IFERROR(F13,0) | I13: =IFERROR(D13,0)+IFERROR(G13,0)
E14: O. 公共 Shell | F14: =SUMIF('3.后台模块'!C:C,E14,'3.后台模块'!G:G) | G14: =SUMIF('3.后台模块'!C:C,E14,'3.后台模块'!I:I) | H14: =IFERROR(C14,0)+IFERROR(F14,0) | I14: =IFERROR(D14,0)+IFERROR(G14,0)
B15: C 端小计 | C15: =SUM(C6:C14) | D15: =SUM(D6:D14) | E15: 后台小计 | F15: =SUM(F6:F14) | G15: =SUM(G6:G14) | H15: =C15+F15 | I15: =D15+G15
B17: 角色单价比照表（可调）
B18: 角色 | C18: 元/人天 | D18: 说明
B19: 前端开发 | C19: 1300 | D19: 含 Web 端与管理后台页面开发
B20: 小程序开发 | C20: 1300 | D20: 含 UniApp 跨端页面与组件
B21: UI 设计师 | C21: 1000 | D21: 含视觉升级、主题与装修
B22: 测试工程师 | C22: 900 | D22: 含功能、回归与上线验收
B24: 开发费用合计（C 端 + 后台） | H24: =H15 | I24: =I15
B25: 税率（增值税） | H25: 0.13 | I25: =I24*H25
B26: 项目总价（含税） | I26: =I24+I25
B28: 备注：
B29: 1. 工作量单位为「人天」，按 8 小时有效工时计算。
B30: 2. 蓝色单元格为可调参数：角色单价、税率、人天；调整后下方所有金额自动重算。
B31: 3. 包含：源代码、PRD 文档、数据库设计、测试用例、部署文档、培训与上线支持。
B32: 4. 不包含：服务器 / 短信 / 支付通道 / 第三方接口年费、设计素材版权采购。
B33: 5. 付款方式：30% 启动 + 40% 中期验收 + 25% 上线 + 5% 质保（3 个月）。
B34: 6. 本报价有效期 30 天，最终以双方合同为准。

Sheet 2.C端模块
A1: 体彩衍生品商城 — C端模块 3 级模块清单
A3: 编号 | B3: 层级 | C3: 一级模块 | D3: 二级模块 | E3: 三级模块 | F3: 角色 | G3: 人天 | H3: 单价（元/天） | I3: 金额（元）
A4: A1 | B4: 3 | C4: A. 首页 | D4: Banner 轮播 | E4: 自动/手动切换 | F4: 前端开发 | G4: 0.4 | H4: =VLOOKUP(F4,'2.C端模块'!$E$76:$F$79,2,FALSE) | I4: =G4*H4
A5: A2 | B5: 3 | C5: A. 首页 | D5: Banner 轮播 | E5: 点击跳转详情/活动页 | F5: 前端开发 | G5: 0.3 | H5: =VLOOKUP(F5,'2.C端模块'!$E$76:$F$79,2,FALSE) | I5: =G5*H5
A6: A3 | B6: 3 | C6: A. 首页 | D6: Banner 轮播 | E6: 营销活动配置拉取 | F6: 前端开发 | G6: 0.3 | H6: =VLOOKUP(F6,'2.C端模块'!$E$76:$F$79,2,FALSE) | I6: =G6*H6
A7: A4 | B7: 3 | C7: A. 首页 | D7: 分类入口 | E7: 4-8 个宫格布局 | F7: 前端开发 | G7: 0.3 | H7: =VLOOKUP(F7,'2.C端模块'!$E$76:$F$79,2,FALSE) | I7: =G7*H7
A8: A5 | B8: 3 | C8: A. 首页 | D8: 分类入口 | E8: 图标与名称渲染 | F8: 前端开发 | G8: 0.3 | H8: =VLOOKUP(F8,'2.C端模块'!$E$76:$F$79,2,FALSE) | I8: =G8*H8
A9: A6 | B9: 3 | C9: A. 首页 | D9: 分类入口 | E9: 点击跳转商品列表 | F9: 前端开发 | G9: 0.2 | H9: =VLOOKUP(F9,'2.C端模块'!$E$76:$F$79,2,FALSE) | I9: =G9*H9
A10: A7 | B10: 3 | C10: A. 首页 | D10: 热门商品 | E10: 商品卡片信息渲染 | F10: 前端开发 | G10: 0.5 | H10: =VLOOKUP(F10,'2.C端模块'!$E$76:$F$79,2,FALSE) | I10: =G10*H10
A11: A8 | B11: 3 | C11: A. 首页 | D11: 热门商品 | E11: 加载更多/分页 | F11: 前端开发 | G11: 0.5 | H11: =VLOOKUP(F11,'2.C端模块'!$E$76:$F$79,2,FALSE) | I11: =G11*H11
A12: A9 | B12: 3 | C12: A. 首页 | D12: 热门商品 | E12: 快捷加入购物车 | F12: 前端开发 | G12: 0.5 | H12: =VLOOKUP(F12,'2.C端模块'!$E$76:$F$79,2,FALSE) | I12: =G12*H12
A13: A10 | B13: 3 | C13: A. 首页 | D13: Tabbar 导航 | E13: 4 个主 Tab 切换 | F13: 前端开发 | G13: 0.3 | H13: =VLOOKUP(F13,'2.C端模块'!$E$76:$F$79,2,FALSE) | I13: =G13*H13
A14: A11 | B14: 3 | C14: A. 首页 | D14: Tabbar 导航 | E14: 未读消息小红点 | F14: 前端开发 | G14: 0.3 | H14: =VLOOKUP(F14,'2.C端模块'!$E$76:$F$79,2,FALSE) | I14: =G14*H14
A15: B1 | B15: 3 | C15: B. 商品 | D15: 分类页 | E15: 左侧一级分类 | F15: 前端开发 | G15: 0.5 | H15: =VLOOKUP(F15,'2.C端模块'!$E$76:$F$79,2,FALSE) | I15: =G15*H15
... A71: F12 | B71: 3 | C71: F. 公共能力 | D71: 公共 Shell | E71: 错误页 / 空状态 / 离线 | F71: 前端开发 | G71: 0.3 | H71: =VLOOKUP(F71,'2.C端模块'!$E$76:$F$79,2,FALSE) | I71: =G71*H71
A72: 合计 | G72: =SUM(G4:G71) | H72: =IFERROR(I72/G72,0) | I72: =SUM(I4:I71)
E74: 角色单价比照表
E75: 角色 | F75: 元/人天
E76: 前端开发 | F76: 1300
E77: 小程序开发 | F77: 1300
E78: UI 设计师 | F78: 1000
E79: 测试工程师 | F79: 900

Sheet 3.后台模块
A1: 体彩衍生品商城 — 后台模块 3 级模块清单
A3: 编号 | B3: 层级 | C3: 一级模块 | D3: 二级模块 | E3: 三级模块 | F3: 角色 | G3: 人天 | H3: 单价（元/天） | I3: 金额（元）
A4: G1 | B4: 3 | C4: G. 系统认证 | D4: 登录 | E4: 账号密码登录 | F4: 前端开发 | G4: 0.6 | H4: =VLOOKUP(F4,'3.后台模块'!$E$75:$F$78,2,FALSE) | I4: =G4*H4
A5: G2 | B5: 3 | C5: G. 系统认证 | D5: 登录 | E5: 图形验证码 | F5: 前端开发 | G5: 0.4 | H5: =VLOOKUP(F5,'3.后台模块'!$E$75:$F$78,2,FALSE) | I5: =G5*H5
A6: G3 | B6: 3 | C6: G. 系统认证 | D6: 登录 | E6: 记住登录 / 自动续签 | F6: 前端开发 | G6: 0.3 | H6: =VLOOKUP(F6,'3.后台模块'!$E$75:$F$78,2,FALSE) | I6: =G6*H6
A7: G4 | B7: 3 | C7: G. 系统认证 | D7: RBAC 权限 | E7: 角色与菜单管理 | F7: 前端开发 | G7: 0.6 | H7: =VLOOKUP(F7,'3.后台模块'!$E$75:$F$78,2,FALSE) | I7: =G7*H7
A8: G5 | B8: 3 | C8: G. 系统认证 | D8: RBAC 权限 | E8: 动态菜单渲染 | F8: 前端开发 | G8: 0.5 | H8: =VLOOKUP(F8,'3.后台模块'!$E$75:$F$78,2,FALSE) | I8: =G8*H8
A9: G6 | B9: 3 | C9: G. 系统认证 | D9: RBAC 权限 | E9: 按钮级操作权限 | F9: 前端开发 | G9: 0.6 | H9: =VLOOKUP(F9,'3.后台模块'!$E$75:$F$78,2,FALSE) | I9: =G9*H9
A10: H1 | B10: 3 | C10: H. 工作台 | D10: 数据看板 | E10: 关键指标卡片（订单/GMV/用户） | F10: 前端开发 | G10: 0.7 | H10: =VLOOKUP(F10,'3.后台模块'!$E$75:$F$78,2,FALSE) | I10: =G10*H10
A11: H2 | B11: 3 | C11: H. 工作台 | D11: 数据看板 | E11: 销售趋势折线图 | F11: 前端开发 | G11: 0.7 | H11: =VLOOKUP(F11,'3.后台模块'!$E$75:$F$78,2,FALSE) | I11: =G11*H11
A12: H3 | B12: 3 | C12: H. 工作台 | D12: 数据看板 | E12: 渠道分布饼图 | F12: 前端开发 | G12: 0.6 | H12: =VLOOKUP(F12,'3.后台模块'!$E$75:$F$78,2,FALSE) | I12: =G12*H12
A13: H4 | B13: 3 | C13: H. 工作台 | D13: 数据看板 | E13: 实时数据刷新 | F13: 前端开发 | G13: 0.5 | H13: =VLOOKUP(F13,'3.后台模块'!$E$75:$F$78,2,FALSE) | I13: =G13*H13
A14: H5 | B14: 3 | C14: H. 工作台 | D14: 数据看板 | E14: 待办事项列表 | F14: 前端开发 | G14: 0.5 | H14: =VLOOKUP(F14,'3.后台模块'!$E$75:$F$78,2,FALSE) | I14: =G14*H14
A15: I1 | B15: 3 | C15: I. 商品管理 | D15: 商品列表 | E15: 多条件筛选 | F15: 前端开发 | G15: 0.5 | H15: =VLOOKUP(F15,'3.后台模块'!$E$75:$F$78,2,FALSE) | I15: =G15*H15
... A70: O6 | B70: 3 | C70: O. 公共 Shell | D70: 通用能力 | E70: 全局错误处理 / 日志 | F70: 前端开发 | G70: 0.5 | H70: =VLOOKUP(F70,'3.后台模块'!$E$75:$F$78,2,FALSE) | I70: =G70*H70
A71: 合计 | G71: =SUM(G4:G70) | H71: =IFERROR(I71/G71,0) | I71: =SUM(I4:I70)
E73: 角色单价比照表
E74: 角色 | F74: 元/人天
E75: 前端开发 | F75: 1300
E76: 小程序开发 | F76: 1300
E77: UI 设计师 | F77: 1000
E78: 测试工程师 | F78: 900

Sheet 4.报价说明
B2: 体彩衍生品商城 — 报价说明
B4: 1. 项目范围
C5: • 本次报价覆盖 C 端小程序（UniApp + Vue 3 + Pinia）与运营管理后台（Vue 3 + Vite + Element Plus）的完整前端开发工作。
C6: • 后端服务（Spring Boot 3.2 + MyBatis Plus + MySQL + Redis）按现有代码基础进行联调与对接。
B7: 2. 计价方式
C8: • 按三级功能模块逐项核算：每个三级模块给出工时（人天），按角色单价折算金额。
C9: • 一级、二级小计使用 SUMIF 公式对三级模块自动汇总。
C10: • 总计 = C 端小计 + 后台小计；项目总价 = 总计 × (1 + 13% 增值税)。
B11: 3. 角色单价依据
C12: • 前端开发 1300 元/人天：参照 2026 年中国中端市场前端工程师外包均价。
C13: • UI 设计师 1000 元/人天：参照中级 UI 设计师外包均价。
C14: • 单价可在「1.报价汇总」右下角或各模块表底部「角色单价比照表」中调整。
B15: 4. 工时估算依据
C16: • 依据现有代码体量、UI 模拟器复杂度、业务流程深度综合评估。
C17: • C 端 13 页面 + 公共能力 ≈ 38 人天；后台 11 页面 + 公共 Shell ≈ 29 人天。
C18: • 含：基础页面、复杂交互（SKU 弹层、订单状态机、退款流程）、可视化配置（Banner 装修、双端同步）。
B19: 5. 包含项
C20: • 全部三级模块对应的源代码、组件库封装。
C21: • 与后端接口联调、Mock 数据、接口文档（Swagger 注释）。
C22: • PRD、数据库设计、测试用例、部署文档（基于现有项目文档）。
C23: • 上线前 2 周问题修复与上线后 3 个月质保。
B24: 6. 不包含项
C25: • 服务器、域名、SSL 证书、短信通道、微信支付通道年费。
C26: • 第三方素材版权采购（图片、字体、图标库）。
C27: • 运营数据初始化、客服培训、推广物料设计。
C28: • 超过 3 个月的免费维护期。
B29: 7. 付款方式
C30: • 30% 合同签订后 5 个工作日内支付（启动款）。
C31: • 40% 中期里程碑（核心模块完成并通过内部测试）验收后支付。
C32: • 25% 系统上线后 5 个工作日内支付。
C33: • 5% 质保金：上线 3 个月无重大问题后支付。
B34: 8. 风险与变更
C35: • 需求变更：单次变更超过 5% 工作量时，按变更工作量单独核算。
C36: • 接口变更：后端接口字段调整超过 10 处时，按 0.5 人天/次补差。
C37: • 紧急加期：项目期间如需加急（< 原周期 70%），加收 20% 费用。
B38: 9. 交付物清单
C39: • C 端小程序源代码（UniApp 跨端工程）。
C40: • 后台管理系统源代码（Vue 3 + Vite + Element Plus）。
C41: • 公共组件库、API 封装、状态管理 Store。
C42: • 与现有后端联调的接口对接说明。
...
